# 18-1 예외처리의 기본

> 피할 수 없다면 처리해주자

- 예외?

  - 프로그램 실행 중 발생하는 **예외적인 상황**
  - 문법 오류라기보다는 실행 중간에 발생하는 의도치 않은 상황

  ```java
  // Exception2.java
  
  import java.util.Scanner;
  
  public class Exception2 {
  
  	public static void main(String[] args) {
  
  		Scanner sc = new Scanner(System.in);
  		int money = sc.nextInt();
  		int people = sc.nextInt();
  		int bigSize = 20000;
  		int mediumSize = 18000;
  		int smallSize = 15000;
  		
  		System.out.println("hello, this is chinese restaurant double dragon." + "\n");
  		
          if(money > bigSize) {
              System.out.println("big size");
              System.out.println("Let's pay it");
              System.out.println("money to pay for each person is " + (bigSize / people));
              System.out.println("Here you are");
  
          }
          else if(money > mediumSize) {
              System.out.println("medium size");
              System.out.println("money to pay for each person is " + (mediumSize / people));
              System.out.println("Here you are");		
          }
          else if(money > smallSize) {
              System.out.println("small size");
              System.out.println("money to pay for each person is " + (smallSize / people));
              System.out.println("Here you are");		
          }
          else {
              System.out.println("go away");
          }
  	}
  }
  ```

  - 코드 자체는 문제가 없음
  - 하지만 정수를 입력해야 하는 money에 문자를 입력하거나, people에 0을 입력한다면?
  - 사용자의 입력에 의해 문제가 발생한다. 이런 상황이 **예외**!
  - JVM은 예외가 발생했을 때 관련 내용을 출력하고 프로그램을 종료해버린다.
    - 가상 머신은 예외의 발생과 그 원인은 알고 있다. 
    - 다만 그게 프로그래머가 원하는 방식의 예외 처리인지 알 수 없기에 단순히 프로그램을 종료하는 것



- 그럼 예외를 어떻게 처리하지? -> try ~ catch

  - 예외마다 예외 상황을 알리는 클래스가 있는데, 그것이 **예외 클래스**
  - 예외가 발생하면, 가상머신은 해당 예외 클래스의 인스턴스를 생성
  - 이 인스턴스를 프로그래머가 처리한다면 예외가 처리된 것으로 간주
  - 하지만 그렇지 않다면 프로그램은 그냥 종료
  - 예외를 처리할 땐 기본적으로 try - catch 문을 사용
  - `try 안에서 발생한 예외를 catch 안에서 처리한다!`
  - 만들어진 예외 클래스의 인스턴스를 catch의 매개변수로 전달한다.
    - 둘 이상의 인스턴스를 `|`를 기준으로 처리 가능!
    - 단순히 예외의 갯수만큼 catch문을 만들어도 되지만, 예외처리 로직이 동일하다면 묶어주자
  - 가상 머신은 이후 예외가 처리되었다고 간주하고 catch문 이후부터 실행을 이어감

  ```java
  // Exception2.java
  
  import java.util.InputMismatchException;
  
  import java.util.Scanner;
  
  public class Exception2 {
  
  	public static void main(String[] args) {
  
  		Scanner sc = new Scanner(System.in);
  		int money = sc.nextInt();
  		int people = sc.nextInt();
  		int bigSize = 20000;
  		int mediumSize = 18000;
  		int smallSize = 15000;
  		
  		System.out.println("hello, this is chinese restaurant double dragon." + "\n");
  		
  		try {
  			if(money > bigSize) {
  				System.out.println("big size");
  				System.out.println("Let's pay it");
  				System.out.println("money to pay for each person is " + (bigSize / people));
  				System.out.println("Here you are");
  				
  			}
  			else if(money > mediumSize) {
  				System.out.println("medium size");
  				System.out.println("money to pay for each person is " + (mediumSize / people));
  				System.out.println("Here you are");		
  			}
  			else if(money > smallSize) {
  				System.out.println("small size");
  				System.out.println("money to pay for each person is " + (smallSize / people));
  				System.out.println("Here you are");		
  			}
  			else {
  				System.out.println("go away");
  			}
  		}
  		catch(ArithmeticException | InputMismatchException e){
  			e.getMessage();
  		}
  	}
  }
  ```

  

- 예외에는 책임이 따른다

  - 자바의 최상위 클래스는 `java.lang.Object`
  - 이거 말고 예외 클래스들의 최상위 클래스는? `java.lang.Throwable!`
  - 이 안에는 예외의 원인이 담긴 문자열을 반환하는 `getMessage()`, 예외 발생 위치와 호출된 메서드 정보를 보여주는 `printStackTrace()` 메서드가 있다.
    - JVM도 프로그램 종료 전 예외 인스턴스의 printStackTrace() 메서드를 호출한다!

  ```java
  // CalcException.java
  
  public class CalcException {
  
  	public static void sum1(int i) {
  		sum2(i, 0);
  	}
  	
  	public static void sum2(int i, int j) {
  		int x = i / j;         // j에 0이 들어가 예외 발생 가능
  	}
  	
  	public static void main(String[] args) {
  
  		sum1(3);
  		System.out.println("Bye Bye");
  	}
  }
  
  // 0으로 나누기 연산을 해서 예외가 발생했다
  Exception in thread "main" java.lang.ArithmeticException: / by zero
  	at ch18.CalcException.sum2(CalcException.java:10) // sum2에서 예외가 발생했고
  	at ch18.CalcException.sum1(CalcException.java:6) // sum1로 책임이 넘어갔으며
  	at ch18.CalcException.main(CalcException.java:15) // main까지 예외의 책임이 넘어갔다.
  ```

  - 무슨 일이 일어난걸까?

    - 예외는 sum2 메서드에서 발생했다. 
    - 하지만 sum2에서는 예외를 처리하지 않았다. 이 경우 가상 머신은 sum2를 호출한 sum1 메서드에 예외처리의 책임을 넘긴다. 책임이 넘어가면, 책임을 넘긴 sum2 메서드의 호출은 종료된다!
    - sum1에서도 예외 처리를 하지 않았고, main 메서드로 넘어간다.
    - main에서도 안 했네? 그러면 가상 머신으로 책임이 넘어가고, 가상 머신이 프로그램을 종료한다.
    - 위의 예시에서의 출력을 보면 예외의 발생 및 이동 경로를 알 수 있다!

  - 정리하면...

    - **예외는 처리하지 않으면 그 책임이 넘어간다!!!**

    ![EP.2 가짜사나이 짤, 유행어, 명대사 모음 : 네이버 블로그](18.assets/SE-921b4feb-b144-4591-a767-24a85ccf55e8-16331118833732.png)

  

  - 예외... 예외를 처리해야 한다

  ```java
  // CalcException2.java
  
  public class CalcException2 {
  
  	public static void sum1(int x) {
  		sum2(x, 0);
  	}
  	
  	public static void sum2(int i, int j) {
  		int x = i / j;
  	}
  	
  	public static void main(String[] args) {
  		// main 메서드 안에서 예외를 처리하고 있다!
          // sum1에서 넘어오는 예외를 처리
  		try {
  			sum1(3);
  		}
          // 실제로 sum1에서부터 넘어오는 예외는 Throwable의 인스턴스가 아니다!!!
          // 다만 저게 가능한 이유는 모든 예외 클래스가 Throwable을 상속하기 때문
  		catch(Throwable e) {
  			e.printStackTrace();
  		}
  		
  		System.out.println("Bye Bye");
  	}
  }
  ```

  

- 다양한 예외들

  ```java
  // VariousExceptionClass.java
  
  // ClassCastException을 위한 부모-자식 클래스 선언
  class ParentClass {}
  class ChildClass extends ParentClass {}
  
  public class VariousExceptionClass {
  
  	public static void main(String[] args) {
  
  		// ArrayIndexOutOfBoundsException
  		
  //		Integer[] arr1 = {1, 2, 3, 4, 5};
  //		for(int i = 0; i < 6; i++) {
  //			System.out.println(arr1[i]);
  //		}
  
  		// ClassCastException
  		
  //		ParentClass cls1 = new ChildClass();
  //		// 참조변수 cls1은 자식 클래스인 ChildClass의 인스턴스를 참조한다.
  //		// 부모 클래스형 참조변수로 자식 클래스의 인스턴스를 참조하는 데에는 아무 문제가 없다!
  //		// 그렇기에 자식 클래스형 참조변수로 자식 클래스로 캐스팅된 cls1(자식 클래스를 참조하는)을 참조하는데 문제가 없는 것!
  //		ChildClass cls2 = (ChildClass)cls1; // it runs
  //		
  //		System.out.println();
  //		
  //		ParentClass cls3 = new ParentClass();
  //		// 다만 그 역은 성립할 수 없다. 자식 클래스형 참조변수로 부모 클래스의 인스턴스를 참조하려는 시도는 불가능하다.
  //		ChildClass cls4 = (ChildClass)cls3; 
  
  		// NullPointerException
  		
  //		String myStr1 = null;
  //		System.out.println(myStr1); // null 출력
  		
  		// Exception! NullPointerException은 null이 저장된 참조변수를 대상으로 메서드를 호출할 때 발생한다.
  //		int lenForStr = myStr1.length();  
  	}
  
  }
  ```

  

# 18-2 예외처리에 대한 다른 정보

> 언제 예외처리가 필요하고, 필요하지 않을까?

- 예외 클래스의 구분

  - 예외 클래스의 최상위 클래스는 Throwable 클래스이다. 이를 상속하는 클래스는 세 종류다.

    - Error
      - IOError: 입출력 관련해서 코드 복구가 불가능한 오류 발생
      - VirtualMachineError: 가상머신에 심각한 오류 발생
      - Error 클래스를 상속하는 예외들은 처리할 수 있는 예외가 아님! 
    - Exception 
      - 여기가 문제
      - 여기는 반드시 예외처리가 필요하다.
    - RuntimeException 
      - 얘는 Exception 클래스를 상속!
      - ArithmeticException, ClassCastException, NullPointerException 등이 해당
      - 이 경우에도 예외처리를 하지 않는다. 
      - 예외처리를 하기보다 원인을 찾아서 코드를 수정하는 경우가 많음

    

  - Exception? 왜 반드시 처리해야 하지?

    - Exception 클래스만 상속하는 예외 클래스가 문제가 된다.

    ```java
    // IOException1.java
    
    import java.nio.file.Path;
    import java.nio.file.Paths;
    import java.nio.file.Files;
    import java.io.BufferedWriter;
    import java.io.IOException;
    
    public class IOException1 {
    
    	public static void main(String[] args) {
    
    		Path file = Paths.get("C://...//ch18//Test.txt");
    		BufferedWriter writer = null;
    		// 반드시 예외처리할 것
    		try {
    			writer = Files.newBufferedWriter(file);
    			writer.write('A');
    			
    			if(writer != null) {
    				writer.close();
    			}
    		}
    		catch(IOException e) {
    			e.printStackTrace();
    		}
    		
            // 아래처럼 예외처리를 생략하면 컴파일 오류가 난다!
            // IOException 예외가 발생할 수 있는 메서드의 호출문에서 오류가 난다.
    		/*
    		 without try ~ catch
    		 
    		Path file = Paths.get("C://java//src//ch18//Test.txt");
    		BufferedWriter writer = null;
    		writer = Files.newBufferedWriter(file);
    		writer.write('A');
    		
    		if(writer != null) {
    			writer.close();
    		}
    		 */
    	}
    
    }
    ```

    - 위처럼 main 안에서 모든 것을 처리할 수도 있지만...

    ```java
    // IOException2.java
    
    import java.nio.file.Path;
    import java.nio.file.Paths;
    import java.nio.file.Files;
    import java.io.BufferedWriter;
    import java.io.IOException;
    
    public class IOException2 {
    
        // 여기에서의 throw는 해당 메서드를 호출한 메서드에게 예외 처리의 책임을 넘긴다는 걸 의미!!
    	public static void method1() throws IOException {
    		method2();
    	}
    	
        // 메서드의 호출 순서는 main -> method1 -> method2
        // 예외처리의 흐름은 method2 -> method1 -> main
    	public static void method2() throws IOException {
    		Path file = Paths.get("C://...//ch18//Test.txt");
    		BufferedWriter writer = null;
    		writer = Files.newBufferedWriter(file);
    		writer.write('A');
    		
    		if(writer != null) {
    			writer.close();
    		}
    	}
    	
    	public static void main(String[] args) {
    
    		try {
    			method1();
    		}
    		catch(IOException e) {
    			e.printStackTrace();
    		}
    	}
    }
    ```

    - 위처럼 throws 키워드를 통해 이 메서드를 호출한 메서드에 처리를 넘길 수도 있다.
    - throws 뒤에 둘 이상의 예외를 적을 수도 있다. `,`로 구분한다.



- 내가 직접 정의하는 예외

  - 프로그래머가 특정한 예외 상황을 정의하고, 이를 처리하게 할 수도 있다.
  - 여기서 정의하는 예외 클래스는 Exception을 상속한다!

  ```java
  // CustomException.java
  
  import java.util.Scanner;
  
  class ReadWeightException extends Exception {
      // 생성자에서 상위 클래스의 생성자를 호출하며 예외 상황에 대한 문자열을 전달
  	public ReadWeightException() {
  		super("it's not valid weight.");
  	}
  }
  
  public class CustomException {
  	
  	public static void main(String[] args) {
  
  		System.out.println("enter your weight: ");
  		
  		try {
  			Integer weight = readWeight();
  			System.out.printf("your weight: %d", weight);
  		}
  		catch(ReadWeightException e) {
  			System.out.println(e.getMessage());
  		}
  	}
  	
  	public static int readWeight() throws ReadWeightException {
  		Scanner scanner = new Scanner(System.in);
  		Integer weight = scanner.nextInt();
  		
          // 몸무게가 음수이면 말이 안 되지
  		if(weight < 0) {   // 예외가 발생하면
  			throw new ReadWeightException();  // 예외 클래스의 인스턴스를 만들고 예외 발생!
  		}
  		
  		return weight;
  	}
  }
  ```

  

- finally

  - try는 혼자 뭘 못해
  - 그래서 try문 뒤에 catch를 붙여주는데, try ~ finally 형식으로도 사용이 가능하다.
  - 여기서 finally는 코드의 실행이 try문 안으로 들어가게 되면, 무조건 실행되게 된다!
    - try에서 예외가 생기던 말던, catch가 실행이 되건 말건, finally는 실행된다.
  - `try ~ catch ~ finally`도 가능하다.
  - finally 안에서 try ~ catch문의 구성도 가능하다!

  ```java
  // IOException3.java
  
  import java.nio.file.Path;
  import java.nio.file.Paths;
  import java.nio.file.Files;
  import java.io.BufferedWriter;
  import java.io.IOException;
  
  public class IOException3 {
  
  	public static void main(String[] args) {
  
  		Path file = Paths.get("C://...//ch18//Test.txt");
  		BufferedWriter writer = null;
  		
  		try {
  			writer = Files.newBufferedWriter(file);
  			writer.write('A');
  		}
  		catch(IOException e) {
  			e.printStackTrace();
  		}
  		finally {       // finally 안에서 try-catch 구성
  			try {       
  				if(writer != null) {
  					writer.close();
  				}
  			} catch (IOException e) {
  				e.printStackTrace();
  			}
  		}
  	}
  }
  ```

  

- try - with - resource

  - finally 구문을 사용하면 좋긴 한데.. 코드가 복잡해진다.
  - 이런 부분을 개선하고자 사용하는 것이 `try - with - resource!!`
  - 여기서 catch 문은 선택이지만, 보통은 포함시킨다.

  ```java
  // IOException4.java
  
  import java.nio.file.Path;
  import java.nio.file.Paths;
  import java.nio.file.Files;
  import java.io.BufferedWriter;
  import java.io.IOException;
  
  public class IOException4 {
  
  	public static void main(String[] args) {
  
  		Path file = Paths.get("C://...//ch18//Test.txt");
  		
          // 소괄호 안에는 종료의 과정을 필요로 하는 리소스를 만들 수 있다!
          // 해당 리소스는 try-with-resource 구문을 빠져나오면서 자동으로 종료된다.
          // 소괄호 안의 내용이 resource
          // try 안에서 예외가 발생하더라도 ok
  		try(BufferedWriter writer = Files.newBufferedWriter(file)) {
  			writer.write('A');
  		}
  		catch(IOException e) {
  			e.printStackTrace();
  		}
  	}
  }
  ```



# 사실 중요한게 있는데

- 예외처리는 성능의 저하를 유발한다.
  - try 안의 코드는 밖의 코드보다 실행 속도가 느리기 때문
  - 과도한 예외처리는 성능의 저하를 불러오는 것!
  - 딱히 예외처리할 이유가 없다면 try문 안에 두지 말자.